Workbook
Name Slicer_Product: #N/A
Name Slicer_Sales: #N/A

Sheet Sales_Transactions
A1: Transaction_ID | B1: Date | C1: Region | D1: Product_ID | E1: Value | F1: Month | G1: Product_Name | H1: Product_Type | I1: Base_Price | J1: Profit_Calculation
A2: TXN-2000 | B2: 46009 | C2: West | D2: P004 | E2: 4209.72 | F2: =TEXT(B2, "mmm") -> Dec | G2: =IFERROR( _xlfn.XLOOKUP(D2, Product_Reference!$A$2:$A$7, Product_Reference!$B$2:$B$7, "Unknown Product"),"Check Reference") -> Cloud Storage | H2: =IF(ISNA(VLOOKUP(D2, Product_Reference!$A$2:$D$7, 3, FALSE)),"Type Not Found",VLOOKUP(D2, Product_Reference!$A$2:$D$7, 3, FALSE)) -> Software | I2: =IFERROR(INDEX(Product_Reference!$D$2:$D$7, MATCH(D2, Product_Reference!$A$2:$A$7, 0)),"N/A") -> 50 | J2: =IFERROR(E2-I2, "Cannot Calculate") -> 4159.72
A3: TXN-2001 | B3: 45669 | C3: North | D3: P002 | E3: 4586.23 | F3: =TEXT(B3, "mmm") -> Jan | G3: =IFERROR( _xlfn.XLOOKUP(D3, Product_Reference!$A$2:$A$7, Product_Reference!$B$2:$B$7, "Unknown Product"),"Check Reference") -> Desktop | H3: =IF(ISNA(VLOOKUP(D3, Product_Reference!$A$2:$D$7, 3, FALSE)),"Type Not Found",VLOOKUP(D3, Product_Reference!$A$2:$D$7, 3, FALSE)) -> Hardware | I3: =IFERROR(INDEX(Product_Reference!$D$2:$D$7, MATCH(D3, Product_Reference!$A$2:$A$7, 0)),"N/A") -> 800 | J3: =IFERROR(E3-I3, "Cannot Calculate") -> 3786.23
A4: TXN-2002 | B4: 45995 | C4: West | D4: P999 | E4: 1877.18 | F4: =TEXT(B4, "mmm") -> Dec | G4: =IFERROR( _xlfn.XLOOKUP(D4, Product_Reference!$A$2:$A$7, Product_Reference!$B$2:$B$7, "Unknown Product"),"Check Reference") -> Unknown Product | H4: =IF(ISNA(VLOOKUP(D4, Product_Reference!$A$2:$D$7, 3, FALSE)),"Type Not Found",VLOOKUP(D4, Product_Reference!$A$2:$D$7, 3, FALSE)) -> Type Not Found | I4: =IFERROR(INDEX(Product_Reference!$D$2:$D$7, MATCH(D4, Product_Reference!$A$2:$A$7, 0)),"N/A") -> N/A | J4: =IFERROR(E4-I4, "Cannot Calculate") -> Cannot Calculate
A5: TXN-2003 | B5: 45984 | C5: Central | D5: P002 | E5: 2691.31 | F5: =TEXT(B5, "mmm") -> Nov | G5: =IFERROR( _xlfn.XLOOKUP(D5, Product_Reference!$A$2:$A$7, Product_Reference!$B$2:$B$7, "Unknown Product"),"Check Reference") -> Desktop | H5: =IF(ISNA(VLOOKUP(D5, Product_Reference!$A$2:$D$7, 3, FALSE)),"Type Not Found",VLOOKUP(D5, Product_Reference!$A$2:$D$7, 3, FALSE)) -> Hardware | I5: =IFERROR(INDEX(Product_Reference!$D$2:$D$7, MATCH(D5, Product_Reference!$A$2:$A$7, 0)),"N/A") -> 800 | J5: =IFERROR(E5-I5, "Cannot Calculate") -> 1891.31
A6: TXN-2004 | B6: 45721 | C6: South | D6: P001 | E6: 4138.66 | F6: =TEXT(B6, "mmm") -> Mar | G6: =IFERROR( _xlfn.XLOOKUP(D6, Product_Reference!$A$2:$A$7, Product_Reference!$B$2:$B$7, "Unknown Product"),"Check Reference") -> Laptop | H6: =IF(ISNA(VLOOKUP(D6, Product_Reference!$A$2:$D$7, 3, FALSE)),"Type Not Found",VLOOKUP(D6, Product_Reference!$A$2:$D$7, 3, FALSE)) -> Hardware | I6: =IFERROR(INDEX(Product_Reference!$D$2:$D$7, MATCH(D6, Product_Reference!$A$2:$A$7, 0)),"N/A") -> 1200 | J6: =IFERROR(E6-I6, "Cannot Calculate") -> 2938.66
A7: TXN-2005 | B7: 45745 | C7: West | D7: P006 | E7: 3787.99 | F7: =TEXT(B7, "mmm") -> Mar | G7: =IFERROR( _xlfn.XLOOKUP(D7, Product_Reference!$A$2:$A$7, Product_Reference!$B$2:$B$7, "Unknown Product"),"Check Reference") -> Keyboard | H7: =IF(ISNA(VLOOKUP(D7, Product_Reference!$A$2:$D$7, 3, FALSE)),"Type Not Found",VLOOKUP(D7, Product_Reference!$A$2:$D$7, 3, FALSE)) -> Accessories | I7: =IFERROR(INDEX(Product_Reference!$D$2:$D$7, MATCH(D7, Product_Reference!$A$2:$A$7, 0)),"N/A") -> 45 | J7: =IFERROR(E7-I7, "Cannot Calculate") -> 3742.99
A8: TXN-2006 | B8: 45733 | C8: East | D8: P003 | E8: 1743.26 | F8: =TEXT(B8, "mmm") -> Mar | G8: =IFERROR( _xlfn.XLOOKUP(D8, Product_Reference!$A$2:$A$7, Product_Reference!$B$2:$B$7, "Unknown Product"),"Check Reference") -> Office Suite | H8: =IF(ISNA(VLOOKUP(D8, Product_Reference!$A$2:$D$7, 3, FALSE)),"Type Not Found",VLOOKUP(D8, Product_Reference!$A$2:$D$7, 3, FALSE)) -> Software | I8: =IFERROR(INDEX(Product_Reference!$D$2:$D$7, MATCH(D8, Product_Reference!$A$2:$A$7, 0)),"N/A") -> 350 | J8: =IFERROR(E8-I8, "Cannot Calculate") -> 1393.26
A9: TXN-2007 | B9: 45698 | C9: West | D9: P002 | E9: 3514.18 | F9: =TEXT(B9, "mmm") -> Feb | G9: =IFERROR( _xlfn.XLOOKUP(D9, Product_Reference!$A$2:$A$7, Product_Reference!$B$2:$B$7, "Unknown Product"),"Check Reference") -> Desktop | H9: =IF(ISNA(VLOOKUP(D9, Product_Reference!$A$2:$D$7, 3, FALSE)),"Type Not Found",VLOOKUP(D9, Product_Reference!$A$2:$D$7, 3, FALSE)) -> Hardware | I9: =IFERROR(INDEX(Product_Reference!$D$2:$D$7, MATCH(D9, Product_Reference!$A$2:$A$7, 0)),"N/A") -> 800 | J9: =IFERROR(E9-I9, "Cannot Calculate") -> 2714.18
A10: TXN-2008 | B10: 45790 | C10: East | D10: P005 | E10: 4428.38 | F10: =TEXT(B10, "mmm") -> May | G10: =IFERROR( _xlfn.XLOOKUP(D10, Product_Reference!$A$2:$A$7, Product_Reference!$B$2:$B$7, "Unknown Product"),"Check Reference") -> Monitor | H10: =IF(ISNA(VLOOKUP(D10, Product_Reference!$A$2:$D$7, 3, FALSE)),"Type Not Found",VLOOKUP(D10, Product_Reference!$A$2:$D$7, 3, FALSE)) -> Hardware | I10: =IFERROR(INDEX(Product_Reference!$D$2:$D$7, MATCH(D10, Product_Reference!$A$2:$A$7, 0)),"N/A") -> 250 | J10: =IFERROR(E10-I10, "Cannot Calculate") -> 4178.38
A11: TXN-2009 | B11: 45721 | C11: East | D11: P002 | E11: 395.13 | F11: =TEXT(B11, "mmm") -> Mar | G11: =IFERROR( _xlfn.XLOOKUP(D11, Product_Reference!$A$2:$A$7, Product_Reference!$B$2:$B$7, "Unknown Product"),"Check Reference") -> Desktop | H11: =IF(ISNA(VLOOKUP(D11, Product_Reference!$A$2:$D$7, 3, FALSE)),"Type Not Found",VLOOKUP(D11, Product_Reference!$A$2:$D$7, 3, FALSE)) -> Hardware | I11: =IFERROR(INDEX(Product_Reference!$D$2:$D$7, MATCH(D11, Product_Reference!$A$2:$A$7, 0)),"N/A") -> 800 | J11: =IFERROR(E11-I11, "Cannot Calculate") -> -404.87
A12: TXN-2010 | B12: 45903 | C12: East | D12: P004 | E12: 3313.2 | F12: =TEXT(B12, "mmm") -> Sep | G12: =IFERROR( _xlfn.XLOOKUP(D12, Product_Reference!$A$2:$A$7, Product_Reference!$B$2:$B$7, "Unknown Product"),"Check Reference") -> Cloud Storage | H12: =IF(ISNA(VLOOKUP(D12, Product_Reference!$A$2:$D$7, 3, FALSE)),"Type Not Found",VLOOKUP(D12, Product_Reference!$A$2:$D$7, 3, FALSE)) -> Software | I12: =IFERROR(INDEX(Product_Reference!$D$2:$D$7, MATCH(D12, Product_Reference!$A$2:$A$7, 0)),"N/A") -> 50 | J12: =IFERROR(E12-I12, "Cannot Calculate") -> 3263.2
A13: TXN-2011 | B13: 45974 | C13: South | D13: P999 | E13: 1784.06 | F13: =TEXT(B13, "mmm") -> Nov | G13: =IFERROR( _xlfn.XLOOKUP(D13, Product_Reference!$A$2:$A$7, Product_Reference!$B$2:$B$7, "Unknown Product"),"Check Reference") -> Unknown Product | H13: =IF(ISNA(VLOOKUP(D13, Product_Reference!$A$2:$D$7, 3, FALSE)),"Type Not Found",VLOOKUP(D13, Product_Reference!$A$2:$D$7, 3, FALSE)) -> Type Not Found | I13: =IFERROR(INDEX(Product_Reference!$D$2:$D$7, MATCH(D13, Product_Reference!$A$2:$A$7, 0)),"N/A") -> N/A | J13: =IFERROR(E13-I13, "Cannot Calculate") -> Cannot Calculate
... A201: TXN-2199 | B201: 45881 | C201: South | D201: P001 | E201: 4014.48 | F201: =TEXT(B201, "mmm") -> Aug | G201: =IFERROR( _xlfn.XLOOKUP(D201, Product_Reference!$A$2:$A$7, Product_Reference!$B$2:$B$7, "Unknown Product"),"Check Reference") -> Laptop | H201: =IF(ISNA(VLOOKUP(D201, Product_Reference!$A$2:$D$7, 3, FALSE)),"Type Not Found",VLOOKUP(D201, Product_Reference!$A$2:$D$7, 3, FALSE)) -> Hardware | I201: =IFERROR(INDEX(Product_Reference!$D$2:$D$7, MATCH(D201, Product_Reference!$A$2:$A$7, 0)),"N/A") -> 1200 | J201: =IFERROR(E201-I201, "Cannot Calculate") -> 2814.48

Sheet Product_Reference
A1: Product_ID | B1: Product_Name | C1: Product_Type | D1: Base_Price
A2: P001 | B2: Laptop | C2: Hardware | D2: 1200
A3: P002 | B3: Desktop | C3: Hardware | D3: 800
A4: P003 | B4: Office Suite | C4: Software | D4: 350
A5: P004 | B5: Cloud Storage | C5: Software | D5: 50
A6: P005 | B6: Monitor | C6: Hardware | D6: 250
A7: P006 | B7: Keyboard | C7: Accessories | D7: 45

Sheet Analysis
A1: A. Total Sales by Region
A2: Region | B2: Total Sales
A3: North | B3: =SUMIFS(Sales_Transactions!E:E, Sales_Transactions!C:C, "North") -> 98799.88
A4: South | B4: =SUMIFS(Sales_Transactions!E:E, Sales_Transactions!C:C, "South") -> 122811.4
A5: East | B5: =SUMIFS(Sales_Transactions!E:E, Sales_Transactions!C:C, "East") -> 88729.04
A6: West | B6: =SUMIFS(Sales_Transactions!E:E, Sales_Transactions!C:C, "West") -> 118542.52
A7: Central | B7: =SUMIFS(Sales_Transactions!E:E, Sales_Transactions!C:C, "Central") -> 77650.29
A9: B. Average Transaction Value by Product Type
A10: Product_Type | B10: Average Value
A11: Hardware | B11: =AVERAGEIFS(Sales_Transactions!E:E, Sales_Transactions!H:H, "Hardware") -> 2626.3877
A12: Software | B12: =AVERAGEIFS(Sales_Transactions!E:E, Sales_Transactions!H:H, "Software") -> 2511.2891
A13: Accessories | B13: =AVERAGEIFS(Sales_Transactions!E:E, Sales_Transactions!H:H, "Accessories") -> 2731.287
A14: Unknown | B14: =AVERAGEIFS(Sales_Transactions!E:E, Sales_Transactions!H:H, "Type Not Found") -> 2211.2157
A16: C. Transaction Counts by Date Range
A18: Date Range | B18: Transaction Count
A19: Q1 (Jan-Mar) | B19: =COUNTIFS(Sales_Transactions!B:B, ">=2025-01-01", Sales_Transactions!B:B, "<=2025-03-31") -> 58
A20: Q2 (Apr-Jun) | B20: =COUNTIFS(Sales_Transactions!B:B, ">=2025-04-01", Sales_Transactions!B:B, "<=2025-06-30") -> 45
A21: Q3 (Jul-Sep) | B21: =COUNTIFS(Sales_Transactions!B:B, ">=2025-07-01", Sales_Transactions!B:B, "<=2025-09-30") -> 46
A22: Q4 (Oct-Dec) | B22: =COUNTIFS(Sales_Transactions!B:B, ">=2025-10-01", Sales_Transactions!B:B, "<=2025-12-31") -> 51
A23: High Value (>3000) | B23: =COUNTIFS(Sales_Transactions!E:E, ">3000") -> 83
A24: Low Value (<1000) | B24: =COUNTIFS(Sales_Transactions!E:E, "<1000") -> 37
A26: 4. Advanced Lookup Demonstrations
A27: INDEX/MATCH Combination Example
A28: In your Analysis sheet, create a product lookup section:
A29: Product_ID | B29: Product_Name (INDEX/MATCH) | C29: Base_Price (INDEX/MATCH)
A30: P001 | B30: =INDEX(Product_Reference!B:B, MATCH("P001", Product_Reference!A:A, 0)) -> Laptop | C30: =INDEX(Product_Reference!D:D, MATCH("P001", Product_Reference!A:A, 0)) -> 1200
A31: P002 | B31: =INDEX(Product_Reference!B:B, MATCH("P002", Product_Reference!A:A, 0)) -> Desktop | C31: =INDEX(Product_Reference!D:D, MATCH("P002", Product_Reference!A:A, 0)) -> 800
A33: XLOOKUP Example
A34: Same table, different functions:
A36: Product_ID | B36: Product_Name (XLOOKUP) | C36: Product_Type (XLOOKUP)
A37: P003 | B37: =_xlfn.XLOOKUP("P003", Product_Reference!A:A, Product_Reference!B:B, "Not Found", 0, 1) -> Office Suite | C37: =_xlfn.XLOOKUP("P003", Product_Reference!A:A, Product_Reference!C:C, "Not Found", 0, 1) -> Software
A38: P004 | B38: =_xlfn.XLOOKUP("P004", Product_Reference!A:A, Product_Reference!B:B, "Not Found", 0, 1) -> Cloud Storage | C38: =_xlfn.XLOOKUP("P004", Product_Reference!A:A, Product_Reference!C:C, "Not Found", 0, 1) -> Software
A40: Comparison Notes:
A41: INDEX/MATCH: More flexible, works in older Excel versions
A42: XLOOKUP: Simpler syntax, can search in any direction, has built-in error handling
A44: 5. Comparison Operators in Conditional Aggregation
A45: A. Sales Analysis with Thresholds
A46: Create a threshold analysis table:
A47: Metric | B47: Formula | C47: Purpose
A48: High-Value Sales (>4000) | B48: =SUMIFS(Sales_Transactions!E:E, Sales_Transactions!E:E, ">4000") -> 195347.39 | C48: Sum of premium transactions
...

Sheet Dashboard
A1: Sales Performance Dashboard | J1: Row Labels | K1: Sum of Sales
A2: =TEXT(TODAY(), "mmmm d, yyyy") & " | Last Updated" -> February 8, 2026 | Last Updated | J2: Monitor | K2: 59903.56
J3: Grand Total | K3: 59903.56
A4: Overall Performance | D4: Regional Analysis | H4: Data Quality
A5: Total Sales: | B5: =IF($K$2="All Time", SUM(Sales_Transactions!E:E), IF($K$2="Q1", SUMIFS(Sales_Transactions!E:E, Sales_Transactions!B:B, ">=2025-01-01", Sales_Transactions!B:B, "<=2025-03-31"), IF($K$2="Q2", SUMIFS(Sales_Transactions!E:E, Sales_Transactions!B:B, ">=2025-04-01", Sales_Transactions!B:B, "<=2025-06-30"), IF($K$2="Q3", SUMIFS(Sales_Transactions!E:E, Sales_Transactions!B:B, ">=2025-07-01", Sales_Transactions!B:B, "<=2025-09-30"), IF($K$2="Q4", SUMIFS(Sales_Transactions!E:E, Sales_Transactions!B:B, ">=2025-10-01", Sales_Transactions!B:B, "<=2025-12-31"), 0))))) -> 0 | D5: Region | E5: Total Sales | F5: # Transactions | G5: Avg. Value | H5: Check | I5: Result
A6: Average Transaction: | B6: =AVERAGE(Sales_Transactions!E:E) -> 2532.6656 | D6: North | E6: =SUMIFS(Sales_Transactions!E:E, Sales_Transactions!C:C, D6) -> 98799.88 | F6: =COUNTIFS(Sales_Transactions!C:C, D6) -> 38 | G6: =IFERROR(E6/F6, 0) -> 2599.9968 | H6: #N/A Errors | I6: =COUNTIF(Sales_Transactions!G:G, "#N/A") -> 0
A7: Total Transactions: | B7: =COUNTA(Sales_Transactions!A:A) -> 201 | D7: South | E7: =SUMIFS(Sales_Transactions!E:E, Sales_Transactions!C:C, D7) -> 122811.4 | F7: =COUNTIFS(Sales_Transactions!C:C, D7) -> 48 | G7: =IFERROR(E7/F7, 0) -> 2558.5708 | H7: Missing Products | I7: =COUNTIF(Sales_Transactions!G:G,"Unknown Product") -> 37
A8: High-Value Sales (>3000): | B8: =COUNTIFS(Sales_Transactions!E:E, ">3000") -> 83 | D8: East | E8: =SUMIFS(Sales_Transactions!E:E, Sales_Transactions!C:C, D8) -> 88729.04 | F8: =COUNTIFS(Sales_Transactions!C:C, D8) -> 36 | G8: =IFERROR(E8/F8, 0) -> 2464.6956 | H8: Date Completeness | I8: =COUNTA(Sales_Transactions!B:B)/COUNTA(Sales_Transactions!A:A) -> 1
A9: Unknown Products (P999): | B9: =COUNTIF(Sales_Transactions!D:D, "P999") -> 37 | D9: West | E9: =SUMIFS(Sales_Transactions!E:E, Sales_Transactions!C:C, D9) -> 118542.52 | F9: =COUNTIFS(Sales_Transactions!C:C, D9) -> 43 | G9: =IFERROR(E9/F9, 0) -> 2756.8028 | H9: Blank Values | I9: =COUNTBLANK(Sales_Transactions!E:E) -> 1048375
D10: Central | E10: =SUMIFS(Sales_Transactions!E:E, Sales_Transactions!C:C, D10) -> 77650.29 | F10: =COUNTIFS(Sales_Transactions!C:C, D10) -> 35 | G10: =IFERROR(E10/F10, 0) -> 2218.5797
A12: Product Type Performance
A13: Product Type | B13: Total Sales | C13: # Products | D13: Avg. Sale | E13: High-Value %
A14: Hardware | B14: =SUMIFS(Sales_Transactions!E:E, Sales_Transactions!H:H, A14) -> 215363.79 | C14: =COUNTIFS(Sales_Transactions!H:H, A14) -> 82 | D14: =IFERROR(B14/C14, 0) -> 2626.3877 | E14: =COUNTIFS(Sales_Transactions!H:H, A14, Sales_Transactions!E:E, ">3000")/C14 -> 0.47560976
A15: Software | B15: =SUMIFS(Sales_Transactions!E:E, Sales_Transactions!H:H, A15) -> 135609.61 | C15: =COUNTIFS(Sales_Transactions!H:H, A15) -> 54 | D15: =IFERROR(B15/C15, 0) -> 2511.2891 | E15: =COUNTIFS(Sales_Transactions!H:H, A15, Sales_Transactions!E:E, ">3000")/C15 -> 0.40740741
A16: Accessories | B16: =SUMIFS(Sales_Transactions!E:E, Sales_Transactions!H:H, A16) -> 73744.75 | C16: =COUNTIFS(Sales_Transactions!H:H, A16) -> 27 | D16: =IFERROR(B16/C16, 0) -> 2731.287 | E16: =COUNTIFS(Sales_Transactions!H:H, A16, Sales_Transactions!E:E, ">3000")/C16 -> 0.44444444
A17: Unknown | B17: =SUMIFS(Sales_Transactions!E:E, Sales_Transactions!H:H, A17) -> 0 | C17: =COUNTIFS(Sales_Transactions!H:H, A17) -> 0 | D17: =IFERROR(B17/C17, 0) -> 0 | E17: =COUNTIFS(Sales_Transactions!H:H, A17, Sales_Transactions!E:E, ">3000")/C17 -> #DIV/0!
A20: Monthly Sales | D20: Top 5 Products
A21: Month | B21: Sales | D21: Product | E21: Sales
A22: Jan | B22: =SUMIFS(Sales_Transactions!E:E, Sales_Transactions!F:F, A22) -> 52371.23 | D22: =INDEX(Product_Reference!B:B, 2) -> Laptop | E22: =SUMIFS(Sales_Transactions!E:E, Sales_Transactions!D:D, "P001") -> 83855.1
A23: Feb | B23: =SUMIFS(Sales_Transactions!E:E, Sales_Transactions!F:F, A23) -> 41053.71 | D23: =INDEX(Product_Reference!B:B, 3) -> Desktop | E23: =SUMIFS(Sales_Transactions!E:E, Sales_Transactions!D:D, "P002") -> 71605.13
A24: Mar | B24: =SUMIFS(Sales_Transactions!E:E, Sales_Transactions!F:F, A24) -> 63666.19 | D24: =INDEX(Product_Reference!B:B, 4) -> Office Suite | E24: =SUMIFS(Sales_Transactions!E:E, Sales_Transactions!D:D, "P003") -> 78390.75
A25: Apr | B25: =SUMIFS(Sales_Transactions!E:E, Sales_Transactions!F:F, A25) -> 43762.57 | D25: =INDEX(Product_Reference!B:B, 5) -> Cloud Storage | E25: =SUMIFS(Sales_Transactions!E:E, Sales_Transactions!D:D, "P004") -> 57218.86
A26: May | B26: =SUMIFS(Sales_Transactions!E:E, Sales_Transactions!F:F, A26) -> 50120.37 | D26: =INDEX(Product_Reference!B:B, 6) -> Monitor | E26: =SUMIFS(Sales_Transactions!E:E, Sales_Transactions!D:D, "P005") -> 59903.56
A27: Jun | B27: =SUMIFS(Sales_Transactions!E:E, Sales_Transactions!F:F, A27) -> 20664.46 | D27: =INDEX(Product_Reference!B:B, 7) -> Keyboard | E27: =SUMIFS(Sales_Transactions!E:E, Sales_Transactions!D:D, "P006") -> 73744.75
A28: Jul | B28: =SUMIFS(Sales_Transactions!E:E, Sales_Transactions!F:F, A28) -> 38662.09
A29: Aug | B29: =SUMIFS(Sales_Transactions!E:E, Sales_Transactions!F:F, A29) -> 34289.47
A30: Sep | B30: =SUMIFS(Sales_Transactions!E:E, Sales_Transactions!F:F, A30) -> 29631.19
A31: Oct | B31: =SUMIFS(Sales_Transactions!E:E, Sales_Transactions!F:F, A31) -> 44470.12
A32: Nov | B32: =SUMIFS(Sales_Transactions!E:E, Sales_Transactions!F:F, A32) -> 30185.16
A33: Dec | B33: =SUMIFS(Sales_Transactions!E:E, Sales_Transactions!F:F, A33) -> 57656.57
